TAP version 13
# _.default.serial.test is not a function
not ok 1 - _.default.serial.test is not a function
  ---
    name: TypeError
    at: 'Object.<anonymous> (bad-test-chain.js:3:13)'
  ...
# No tests found in test/fixture/report/regular/bad-test-chain.js
not ok 2 - No tests found in test/fixture/report/regular/bad-test-chain.js
# slow â€º slow
ok 3 - slow [90m[2mâ€º[22m[39m slow
# unhandled-rejection â€º passes
ok 4 - unhandled-rejection [90m[2mâ€º[22m[39m passes
# unhandled-rejection â€º unhandled non-error rejection
ok 5 - unhandled-rejection [90m[2mâ€º[22m[39m unhandled non-error rejection
# Can't catch me
not ok 6 - Can't catch me
  ---
    name: Error
    at: 'Test.t [as fn] (unhandled-rejection.js:4:17)'
  ...
# null
not ok 7 - null
  ---
    {}
  ...
# uncaught-exception â€º passes
ok 8 - uncaught-exception [90m[2mâ€º[22m[39m passes
# Can't catch me
not ok 9 - Can't catch me
  ---
    name: Error
    at: 'Timeout.setTimeout (uncaught-exception.js:5:9)'
  ...
stdout
stderr
# test â€º skip
ok 10 - test [90m[2mâ€º[22m[39m skip # SKIP
# test â€º todo
not ok 11 - test [90m[2mâ€º[22m[39m todo # TODO
# test â€º passes
ok 12 - test [90m[2mâ€º[22m[39m passes
# test â€º fails
not ok 13 - test [90m[2mâ€º[22m[39m fails
  ---
    name: AssertionError
    message: Test failed via `t.fail()`
    assertion: fail
    at: 'Test.t [as fn] (test.js:12:22)'
  ...
# test â€º known failure
ok 14 - test [90m[2mâ€º[22m[39m known failure
# test â€º no longer failing
not ok 15 - test [90m[2mâ€º[22m[39m no longer failing
  ---
    name: Error
    message: >-
      Test was expected to fail, but succeeded, you should stop marking the test as
      failing
  ...
# test â€º logs
not ok 16 - test [90m[2mâ€º[22m[39m logs
  * hello
  * world
  ---
    name: AssertionError
    message: Test failed via `t.fail()`
    assertion: fail
    at: 'Test.t [as fn] (test.js:21:4)'
  ...
# test â€º formatted
not ok 17 - test [90m[2mâ€º[22m[39m formatted
  ---
    name: AssertionError
    assertion: deepEqual
    values:
      'Difference:': |-
        - 'foo'
        + 'bar'
    at: 'Test.t [as fn] (test.js:25:4)'
  ...
# test â€º power-assert
not ok 18 - test [90m[2mâ€º[22m[39m power-assert
  ---
    name: AssertionError
    assertion: 'true'
    values:
      'Value is not `true`:': 'false'
    at: 'Test.t [as fn] (test.js:30:2)'
  ...
# test â€º bad throws
not ok 19 - test [90m[2mâ€º[22m[39m bad throws
  ---
    name: AssertionError
    message: Improper usage of `t.throws()` detected
    assertion: throws
    values:
      'The following error was thrown, possibly before `t.throws()` could be called:': |-
        Error {
          message: 'err',
        }
    at: 'fn (test.js:35:9)'
  ...
# test â€º bad notThrows
not ok 20 - test [90m[2mâ€º[22m[39m bad notThrows
  ---
    name: AssertionError
    message: Improper usage of `t.notThrows()` detected
    assertion: notThrows
    values:
      'The following error was thrown, possibly before `t.notThrows()` could be called:': |-
        Error {
          message: 'err',
        }
    at: 'fn (test.js:42:9)'
  ...
# test â€º implementation throws non-error
not ok 21 - test [90m[2mâ€º[22m[39m implementation throws non-error
  ---
    name: AssertionError
    message: Error thrown in test
    values:
      'Error thrown in test:': 'null'
  ...

1..14
# tests 14
# pass 5
# skip 1
# fail 13

